<sdf version='1.10'>
  <model name='kobuki_standalone'>
    <link name='base_footprint'>
      <inertial>
        <pose>0.0098661190269689787 2.5606079378846071e-05 0.010277074298930331 0 0 0</pose>
        <mass>2.4213</mass>
        <inertia>
          <ixx>0.022404373200837411</ixx>
          <ixy>-2.8921269603279239e-06</ixy>
          <ixz>4.107367532812852e-06</ixz>
          <iyy>0.022623695892294831</iyy>
          <iyz>-1.2476213934663191e-06</iyz>
          <izz>0.039483407004343579</izz>
        </inertia>
      </inertial>
      <collision name='base_footprint_fixed_joint_lump__base_collision'>
        <pose>0 0 0.069690000000000002 0 0 0</pose>
        <geometry>
          <cylinder>
            <length>0.10938000000000001</length>
            <radius>0.17799999999999999</radius>
          </cylinder>
        </geometry>
      </collision>
      <collision name='base_footprint_fixed_joint_lump__caster_back_link_collision_1'>
        <pose>-0.13500000000000001 0 0.019199999999999998 -1.5707963267948959 0 0</pose>
        <geometry>
          <cylinder>
            <length>0.017600000000000001</length>
            <radius>0.017000000000000001</radius>
          </cylinder>
        </geometry>
        <surface>
          <contact>
            <ode>
              <kp>1000000</kp>
              <kd>100</kd>
              <max_vel>1</max_vel>
              <min_depth>0.001</min_depth>
            </ode>
          </contact>
          <friction>
            <ode>
              <mu>0</mu>
              <mu2>0</mu2>
            </ode>
          </friction>
        </surface>
      </collision>
      <collision name='base_footprint_fixed_joint_lump__caster_front_link_collision_2'>
        <pose>0.115 0 0.0172 -1.5707963267948959 0 0</pose>
        <geometry>
          <cylinder>
            <length>0.017600000000000001</length>
            <radius>0.017000000000000001</radius>
          </cylinder>
        </geometry>
        <surface>
          <contact>
            <ode>
              <kp>1000000</kp>
              <kd>100</kd>
              <max_vel>1</max_vel>
              <min_depth>0.001</min_depth>
            </ode>
          </contact>
          <friction>
            <ode>
              <mu>0</mu>
              <mu2>0</mu2>
            </ode>
          </friction>
        </surface>
      </collision>
      <visual name='base_footprint_fixed_joint_lump__base_link_visual'>
        <pose>0.001 0 0.062190000000000002 0 0 0</pose>
        <geometry>
          <mesh>
            <scale>1 1 1</scale>
            <uri>model://kobuki_description/meshes/main_body.dae</uri>
          </mesh>
        </geometry>
      </visual>
      <sensor name='bumpers' type='contact'>
        <always_on>true</always_on>
        <update_rate>50</update_rate>
        <visualize>true</visualize>
        <contact>
          <collision>base_footprint_fixed_joint_lump__base_collision</collision>
          <topic>__default_topic__</topic>
        </contact>
        <pose>0 0 0.010200000000000001 0 0 0</pose>
      </sensor>
      <sensor name='cliff_sensor_front' type='ray'>
        <always_on>true</always_on>
        <update_rate>50</update_rate>
        <visualize>true</visualize>
        <ray>
          <scan>
            <horizontal>
              <samples>50</samples>
              <resolution>1</resolution>
              <min_angle>-0.0436</min_angle>
              <max_angle>0.0436</max_angle>
            </horizontal>
          </scan>
          <range>
            <min>0.01</min>
            <max>0.14999999999999999</max>
            <resolution>1</resolution>
          </range>
        </ray>
        <pose>0.156 0 0.031600000000000003 3.1415926535897931 1.5707926536359933 3.1415926535897931</pose>
      </sensor>
      <sensor name='cliff_sensor_left' type='ray'>
        <always_on>true</always_on>
        <update_rate>50</update_rate>
        <visualize>true</visualize>
        <ray>
          <scan>
            <horizontal>
              <samples>50</samples>
              <resolution>1</resolution>
              <min_angle>-0.0436</min_angle>
              <max_angle>0.0436</max_angle>
            </horizontal>
          </scan>
          <range>
            <min>0.01</min>
            <max>0.14999999999999999</max>
            <resolution>1</resolution>
          </range>
        </ray>
        <pose>0.087340000000000001 0.13600999999999999 0.031600000000000003 3.1415926535897931 1.5707926536359933 3.1415926535897931</pose>
      </sensor>
      <sensor name='cliff_sensor_right' type='ray'>
        <always_on>true</always_on>
        <update_rate>50</update_rate>
        <visualize>true</visualize>
        <ray>
          <scan>
            <horizontal>
              <samples>50</samples>
              <resolution>1</resolution>
              <min_angle>-0.0436</min_angle>
              <max_angle>0.0436</max_angle>
            </horizontal>
          </scan>
          <range>
            <min>0.01</min>
            <max>0.14999999999999999</max>
            <resolution>1</resolution>
          </range>
        </ray>
        <pose>0.085000000000000006 -0.13600999999999999 0.031600000000000003 3.1415926535897931 1.5707926536359933 3.1415926535897931</pose>
      </sensor>
      <sensor name='imu' type='imu'>
        <plugin name='gazebo_ros_imu_controller' filename='libgazebo_ros_imu_sensor.so'>
          <ros>
            <argument>~/out:=imu</argument>
          </ros>
          <output_type>sensor_msgs/msg/Imu</output_type>
          <body_name>gyro_link</body_name>
          <frame_name>gyro_link</frame_name>
        </plugin>
        <always_on>true</always_on>
        <update_rate>50</update_rate>
        <visualize>false</visualize>
        <imu>
          <noise>
            <type>gaussian</type>
            <rate>
              <mean>0.0</mean>
              <stddev>1.96e-06</stddev>
              <bias_mean>0.0</bias_mean>
              <bias_stddev>0.0</bias_stddev>
            </rate>
            <accel>
              <mean>0.0</mean>
              <stddev>1.7e-2</stddev>
              <bias_mean>0.1</bias_mean>
              <bias_stddev>0.001</bias_stddev>
            </accel>
          </noise>
        </imu>
        <pose>0.056000000000000001 0.062 0.0304 0 0 0</pose>
      </sensor>
    </link>
    <joint name='wheel_left_joint' type='revolute'>
      <pose relative_to='base_footprint'>0 0.115 0.035200000000000002 -1.5707963267948959 0 0</pose>
      <parent>base_footprint</parent>
      <child>wheel_left_link</child>
      <axis>
        <xyz>0 0 1</xyz>
        <limit>
          <lower>-inf</lower>
          <upper>inf</upper>
        </limit>
        <dynamics>
          <spring_reference>0</spring_reference>
          <spring_stiffness>0</spring_stiffness>
        </dynamics>
      </axis>
    </joint>
    <link name='wheel_left_link'>
      <pose relative_to='wheel_left_joint'>0 0 0 0 0 0</pose>
      <inertial>
        <pose>0 0 0 0 0 0</pose>
        <mass>0.01</mass>
        <inertia>
          <ixx>0.001</ixx>
          <ixy>0</ixy>
          <ixz>0</ixz>
          <iyy>0.001</iyy>
          <iyz>0</iyz>
          <izz>0.001</izz>
        </inertia>
      </inertial>
      <collision name='wheel_left_link_collision'>
        <pose>0 0 0 0 0 0</pose>
        <geometry>
          <cylinder>
            <length>0.0206</length>
            <radius>0.035000000000000003</radius>
          </cylinder>
        </geometry>
        <surface>
          <contact>
            <ode>
              <kp>1000000</kp>
              <kd>100</kd>
              <max_vel>1</max_vel>
              <min_depth>0.001</min_depth>
            </ode>
          </contact>
          <friction>
            <ode>
              <mu>1</mu>
              <mu2>1</mu2>
            </ode>
          </friction>
        </surface>
      </collision>
      <visual name='wheel_left_link_visual'>
        <pose>0 0 0 0 0 0</pose>
        <geometry>
          <mesh>
            <scale>1 1 1</scale>
            <uri>model://kobuki_description/meshes/wheel.dae</uri>
          </mesh>
        </geometry>
      </visual>
    </link>
    <joint name='wheel_right_joint' type='revolute'>
      <pose relative_to='base_footprint'>0 -0.115 0.035200000000000002 -1.5707963267948959 0 0</pose>
      <parent>base_footprint</parent>
      <child>wheel_right_link</child>
      <axis>
        <xyz>0 0 1</xyz>
        <limit>
          <lower>-inf</lower>
          <upper>inf</upper>
        </limit>
        <dynamics>
          <spring_reference>0</spring_reference>
          <spring_stiffness>0</spring_stiffness>
        </dynamics>
      </axis>
    </joint>
    <link name='wheel_right_link'>
      <pose relative_to='wheel_right_joint'>0 0 0 0 0 0</pose>
      <inertial>
        <pose>0 0 0 0 0 0</pose>
        <mass>0.01</mass>
        <inertia>
          <ixx>0.001</ixx>
          <ixy>0</ixy>
          <ixz>0</ixz>
          <iyy>0.001</iyy>
          <iyz>0</iyz>
          <izz>0.001</izz>
        </inertia>
      </inertial>
      <collision name='wheel_right_link_collision'>
        <pose>0 0 0 0 0 0</pose>
        <geometry>
          <cylinder>
            <length>0.0206</length>
            <radius>0.035000000000000003</radius>
          </cylinder>
        </geometry>
        <surface>
          <contact>
            <ode>
              <kp>1000000</kp>
              <kd>100</kd>
              <max_vel>1</max_vel>
              <min_depth>0.001</min_depth>
            </ode>
          </contact>
          <friction>
            <ode>
              <mu>1</mu>
              <mu2>1</mu2>
            </ode>
          </friction>
        </surface>
      </collision>
      <visual name='wheel_right_link_visual'>
        <pose>0 0 0 0 0 0</pose>
        <geometry>
          <mesh>
            <scale>1 1 1</scale>
            <uri>model://kobuki_description/meshes/wheel.dae</uri>
          </mesh>
        </geometry>
      </visual>
    </link>
    <plugin name='differential_drive_controller' filename='libgazebo_ros_diff_drive.so'>
      <update_rate>10</update_rate>
      <left_joint>wheel_left_joint</left_joint>
      <right_joint>wheel_right_joint</right_joint>
      <wheel_separation>0.230</wheel_separation>
      <wheel_diameter>0.070</wheel_diameter>
      <max_wheel_torque>1.0</max_wheel_torque>
      <max_wheel_acceleration>1.0</max_wheel_acceleration>
      <command_topic>cmd_vel</command_topic>
      <publish_odom>true</publish_odom>
      <publish_odom_tf>true</publish_odom_tf>
      <publish_wheel_tf>true</publish_wheel_tf>
      <odometry_topic>odom</odometry_topic>
      <odometry_frame>odom</odometry_frame>
      <robot_base_frame>base_link</robot_base_frame>
    </plugin>
    <frame name='caster_back_joint' attached_to='base_link'>
      <pose>-0.13500000000000001 0 0.0089999999999999993 -1.5707963267948959 0 0</pose>
    </frame>
    <frame name='caster_back_link' attached_to='caster_back_joint'>
      <pose>0 0 0 0 0 0</pose>
    </frame>
    <frame name='caster_front_joint' attached_to='base_link'>
      <pose>0.115 0 0.0070000000000000001 -1.5707963267948959 0 0</pose>
    </frame>
    <frame name='caster_front_link' attached_to='caster_front_joint'>
      <pose>0 0 0 0 0 0</pose>
    </frame>
    <frame name='cliff_sensor_front_joint' attached_to='base_link'>
      <pose>0.156 0 0.021399999999999999 0 1.5707963267948966 0</pose>
    </frame>
    <frame name='cliff_sensor_front_link' attached_to='cliff_sensor_front_joint'>
      <pose>0 0 0 0 0 0</pose>
    </frame>
    <frame name='cliff_sensor_left_joint' attached_to='base_link'>
      <pose>0.087340000000000001 0.13600999999999999 0.021399999999999999 0 1.5707963267948966 0</pose>
    </frame>
    <frame name='cliff_sensor_left_link' attached_to='cliff_sensor_left_joint'>
      <pose>0 0 0 0 0 0</pose>
    </frame>
    <frame name='cliff_sensor_right_joint' attached_to='base_link'>
      <pose>0.085000000000000006 -0.13600999999999999 0.021399999999999999 0 1.5707963267948966 0</pose>
    </frame>
    <frame name='cliff_sensor_right_link' attached_to='cliff_sensor_right_joint'>
      <pose>0 0 0 0 0 0</pose>
    </frame>
    <frame name='gyro_joint' attached_to='base_link'>
      <pose>0.056000000000000001 0.062 0.020199999999999999 0 0 0</pose>
    </frame>
    <frame name='gyro_link' attached_to='gyro_joint'>
      <pose>0 0 0 0 0 0</pose>
    </frame>
    <static>false</static>
    <frame name='base_joint' attached_to='base_footprint'>
      <pose>0 0 0.010200000000000001 0 0 0</pose>
    </frame>
    <frame name='base_link' attached_to='base_joint'>
      <pose>0 0 0 0 0 0</pose>
    </frame>
  </model>
</sdf>
